<?xml version="1.0" encoding="UTF-8"?>
<!-- Generated by org.testng.reporters.JUnitXMLReporter -->
<testsuite hostname="ASDP1493PO01976" ignored="0" name="Default test" tests="5" failures="1" timestamp="26 Jun 2018 08:00:54 GMT" time="0.126" errors="0">
  <testcase name="check_game_in_progress" time="0.006" classname="com.qainfotech.tap.training.snl.api.AppTest">
    <failure type="org.json.JSONException" message="JSONArray[0] not found.">
      <![CDATA[org.json.JSONException: JSONArray[0] not found.
	at org.json.JSONArray.get(JSONArray.java:201)
	at org.json.JSONArray.getJSONObject(JSONArray.java:364)
	at com.qainfotech.tap.training.snl.api.Board.rollDice(Board.java:131)
	at com.qainfotech.tap.training.snl.api.AppTest.check_game_in_progress(AppTest.java:72)
	at sun.reflect.NativeMethodAccessorImpl.invoke0(Native Method)
	at sun.reflect.NativeMethodAccessorImpl.invoke(Unknown Source)
	at sun.reflect.DelegatingMethodAccessorImpl.invoke(Unknown Source)
	at java.lang.reflect.Method.invoke(Unknown Source)
	at org.testng.internal.MethodInvocationHelper.invokeMethod(MethodInvocationHelper.java:104)
	at org.testng.internal.Invoker.invokeMethod(Invoker.java:645)
	at org.testng.internal.Invoker.invokeTestMethod(Invoker.java:851)
	at org.testng.internal.Invoker.invokeTestMethods(Invoker.java:1177)
	at org.testng.internal.TestMethodWorker.invokeTestMethods(TestMethodWorker.java:129)
	at org.testng.internal.TestMethodWorker.run(TestMethodWorker.java:112)
	at org.testng.TestRunner.privateRun(TestRunner.java:756)
	at org.testng.TestRunner.run(TestRunner.java:610)
	at org.testng.SuiteRunner.runTest(SuiteRunner.java:387)
	at org.testng.SuiteRunner.runSequentially(SuiteRunner.java:382)
	at org.testng.SuiteRunner.privateRun(SuiteRunner.java:340)
	at org.testng.SuiteRunner.run(SuiteRunner.java:289)
	at org.testng.SuiteRunnerWorker.runSuite(SuiteRunnerWorker.java:52)
	at org.testng.SuiteRunnerWorker.run(SuiteRunnerWorker.java:86)
	at org.testng.TestNG.runSuitesSequentially(TestNG.java:1293)
	at org.testng.TestNG.runSuitesLocally(TestNG.java:1218)
	at org.testng.TestNG.runSuites(TestNG.java:1133)
	at org.testng.TestNG.run(TestNG.java:1104)
	at org.testng.remote.AbstractRemoteTestNG.run(AbstractRemoteTestNG.java:114)
	at org.testng.remote.RemoteTestNG.initAndRun(RemoteTestNG.java:251)
	at org.testng.remote.RemoteTestNG.main(RemoteTestNG.java:77)
]]>
    </failure>
  </testcase> <!-- check_game_in_progress -->
  <testcase name="check_samename_player_exists" time="0.018" classname="com.qainfotech.tap.training.snl.api.AppTest"/>
  <testcase name="check_turn_is_invalid" time="0.002" classname="com.qainfotech.tap.training.snl.api.AppTest"/>
  <testcase name="delete_player_incorrect_uid" time="0.008" classname="com.qainfotech.tap.training.snl.api.AppTest"/>
  <testcase name="max_player" time="0.015" classname="com.qainfotech.tap.training.snl.api.AppTest"/>
</testsuite> <!-- Default test -->
